Workbook

Sheet LEEME
A1: Base de datos: lluvia en El Bosque (P70) · 4 de octubre de 2026
A3: Propósito | B3: Sustento numérico del informe «Intensidad de la lluvia del 4 de octubre de 2026 en El Bosque» y del cuaderno de Google Colab que lo reproduce.
A4: Hojas | B4: Parametros (umbrales) · Diario (series diarias P70 y P28) · Horario (4 eventos, 24 horas) · Indicadores (fórmulas) · Top_diario · Antecedentes.
A5: Fuente diaria | B5: Reportes de datos hidrometeorológicos, variable Precipitación-Diario, estaciones P70 CC El Bosque y P28 Cruz Loma (archivos entregados por el usuario). Periodo 01/01/2020 a 05/10/2026.
A6: Fuente horaria | B6: Gráficos «Precipitación (Horario)» de la estación, leídos a ojo desde la imagen. Margen de lectura: ±0,3 mm por hora. NO es la serie original: reemplazar por la descarga horaria cuando esté disponible (hoja Horario, columna C).
A7: Control | B7: La suma horaria reproduce el total diario con diferencias de décimas (ver hoja Indicadores, fila «Diferencia horaria − diaria»).
A8: Vacíos | B8: Cruz Loma (P28) no tiene datos desde el 05/04/2026. El Bosque (P70) tiene vacíos en 2026 y no tiene dato el 05/10/2026. Las celdas vacías son datos faltantes, no ceros.
A9: Coordenadas | B9: P70: Latitud 9982112,95 · Longitud 500293,65. P28: Latitud 9979839,05 · Longitud 495770,84. UTM WGS 84, tal como figuran en el reporte (la zona UTM no se indica).
A10: Convención de clases | B10: Ligera < 2,5 mm/h · Moderada 2,5 a 7,6 · Fuerte 7,6 a 50 · Violenta > 50. Convención internacional de uso común; no es una clasificación institucional. Se modifica en la hoja Parametros.
A11: Colores | B11: Azul = dato ingresado o leído · Negro = fórmula · Fondo amarillo = parámetro que se puede cambiar.

Sheet Parametros
A1: Parámetros de clasificación de la intensidad horaria
A3: Parámetro | B3: Valor | C3: Unidad | D3: Nota
A4: Mínimo para considerar hora con lluvia | B4: 0.05 | C4: mm | D4: Por debajo se clasifica «Sin lluvia»
A5: Límite ligera / moderada | B5: 2.5 | C5: mm/h | D5: Convención internacional
A6: Límite moderada / fuerte | B6: 7.6 | C6: mm/h | D6: Convención internacional
A7: Límite fuerte / violenta | B7: 50 | C7: mm/h | D7: Convención internacional
A8: Umbral de «hora con lluvia» | B8: 1 | C8: mm | D8: Para contar horas con ≥ 1 mm
A9: Umbral de acumulado | B9: 50 | C9: mm | D9: Para «tiempo para acumular 50 mm»

Sheet Diario
A1: Fecha | B1: El Bosque P70 (mm) | C1: Cruz Loma P28 (mm) | D1: Posición P70 (1 = mayor) | F1: La posición desempata días con igual valor por orden cronológico.
A2: 43831 | B2: 39.9 | C2: 35.2 | D2: =IF(B2="","",RANK(B2,$B$2:$B$2471)+COUNTIF($B$2:B2,B2)-1) -> 17
A3: 43832 | B3: 16.2 | C3: 11.3 | D3: =IF(B3="","",RANK(B3,$B$2:$B$2471)+COUNTIF($B$2:B3,B3)-1) -> 165
A4: 43833 | B4: 0.2 | C4: 0.7 | D4: =IF(B4="","",RANK(B4,$B$2:$B$2471)+COUNTIF($B$2:B4,B4)-1) -> 957
A5: 43834 | B5: 0 | C5: 0 | D5: =IF(B5="","",RANK(B5,$B$2:$B$2471)+COUNTIF($B$2:B5,B5)-1) -> 1058
A6: 43835 | B6: 1.3 | C6: 0.2 | D6: =IF(B6="","",RANK(B6,$B$2:$B$2471)+COUNTIF($B$2:B6,B6)-1) -> 748
A7: 43836 | B7: 3.9 | C7: 4.4 | D7: =IF(B7="","",RANK(B7,$B$2:$B$2471)+COUNTIF($B$2:B7,B7)-1) -> 556
A8: 43837 | B8: 0 | C8: 0.1 | D8: =IF(B8="","",RANK(B8,$B$2:$B$2471)+COUNTIF($B$2:B8,B8)-1) -> 1059
A9: 43838 | B9: 0 | C9: 0 | D9: =IF(B9="","",RANK(B9,$B$2:$B$2471)+COUNTIF($B$2:B9,B9)-1) -> 1060
A10: 43839 | B10: 0 | C10: 0 | D10: =IF(B10="","",RANK(B10,$B$2:$B$2471)+COUNTIF($B$2:B10,B10)-1) -> 1061
A11: 43840 | B11: 0 | C11: 0 | D11: =IF(B11="","",RANK(B11,$B$2:$B$2471)+COUNTIF($B$2:B11,B11)-1) -> 1062
A12: 43841 | B12: 0 | C12: 0 | D12: =IF(B12="","",RANK(B12,$B$2:$B$2471)+COUNTIF($B$2:B12,B12)-1) -> 1063
A13: 43842 | B13: 0 | C13: 0 | D13: =IF(B13="","",RANK(B13,$B$2:$B$2471)+COUNTIF($B$2:B13,B13)-1) -> 1064
... A24: 43853 | B24: 0 | C24: 0 | D24: =IF(B24="","",RANK(B24,$B$2:$B$2471)+COUNTIF($B$2:B24,B24)-1) -> 1071
A25: 43854 | B25: 8.5 | D25: =IF(B25="","",RANK(B25,$B$2:$B$2471)+COUNTIF($B$2:B25,B25)-1) -> 347
A26: 43855 | B26: 0 | D26: =IF(B26="","",RANK(B26,$B$2:$B$2471)+COUNTIF($B$2:B26,B26)-1) -> 1072
A27: 43856 | B27: 0 | D27: =IF(B27="","",RANK(B27,$B$2:$B$2471)+COUNTIF($B$2:B27,B27)-1) -> 1073
A28: 43857 | B28: 4.6 | D28: =IF(B28="","",RANK(B28,$B$2:$B$2471)+COUNTIF($B$2:B28,B28)-1) -> 505
A29: 43858 | B29: 0 | D29: =IF(B29="","",RANK(B29,$B$2:$B$2471)+COUNTIF($B$2:B29,B29)-1) -> 1074
A30: 43859 | B30: 2.9 | D30: =IF(B30="","",RANK(B30,$B$2:$B$2471)+COUNTIF($B$2:B30,B30)-1) -> 607
A31: 43860 | B31: 0 | D31: =IF(B31="","",RANK(B31,$B$2:$B$2471)+COUNTIF($B$2:B31,B31)-1) -> 1075
A32: 43861 | B32: 0 | D32: =IF(B32="","",RANK(B32,$B$2:$B$2471)+COUNTIF($B$2:B32,B32)-1) -> 1076
A33: 43862 | B33: 0.1 | D33: =IF(B33="","",RANK(B33,$B$2:$B$2471)+COUNTIF($B$2:B33,B33)-1) -> 1002
A34: 43863 | B34: 0 | D34: =IF(B34="","",RANK(B34,$B$2:$B$2471)+COUNTIF($B$2:B34,B34)-1) -> 1077
A35: 43864 | B35: 0 | D35: =IF(B35="","",RANK(B35,$B$2:$B$2471)+COUNTIF($B$2:B35,B35)-1) -> 1078
A36: 43865 | B36: 0 | D36: =IF(B36="","",RANK(B36,$B$2:$B$2471)+COUNTIF($B$2:B36,B36)-1) -> 1079
... A44: 43873 | B44: 0 | D44: =IF(B44="","",RANK(B44,$B$2:$B$2471)+COUNTIF($B$2:B44,B44)-1) -> 1085
A45: 43874 | B45: 0 | C45: 0 | D45: =IF(B45="","",RANK(B45,$B$2:$B$2471)+COUNTIF($B$2:B45,B45)-1) -> 1086
A46: 43875 | B46: 0 | C46: 0.1 | D46: =IF(B46="","",RANK(B46,$B$2:$B$2471)+COUNTIF($B$2:B46,B46)-1) -> 1087
A47: 43876 | B47: 0 | C47: 0 | D47: =IF(B47="","",RANK(B47,$B$2:$B$2471)+COUNTIF($B$2:B47,B47)-1) -> 1088
A48: 43877 | B48: 0 | C48: 0 | D48: =IF(B48="","",RANK(B48,$B$2:$B$2471)+COUNTIF($B$2:B48,B48)-1) -> 1089
A49: 43878 | B49: 0 | C49: 0 | D49: =IF(B49="","",RANK(B49,$B$2:$B$2471)+COUNTIF($B$2:B49,B49)-1) -> 1090
A50: 43879 | B50: 0 | C50: 0 | D50: =IF(B50="","",RANK(B50,$B$2:$B$2471)+COUNTIF($B$2:B50,B50)-1) -> 1091
A51: 43880 | B51: 0 | C51: 0 | D51: =IF(B51="","",RANK(B51,$B$2:$B$2471)+COUNTIF($B$2:B51,B51)-1) -> 1092
A52: 43881 | B52: 0.2 | C52: 0.1 | D52: =IF(B52="","",RANK(B52,$B$2:$B$2471)+COUNTIF($B$2:B52,B52)-1) -> 959
A53: 43882 | B53: 7.6 | C53: 11.1 | D53: =IF(B53="","",RANK(B53,$B$2:$B$2471)+COUNTIF($B$2:B53,B53)-1) -> 378
A54: 43883 | B54: 15.8 | C54: 15.8 | D54: =IF(B54="","",RANK(B54,$B$2:$B$2471)+COUNTIF($B$2:B54,B54)-1) -> 172
A55: 43884 | B55: 8.2 | C55: 14.3 | D55: =IF(B55="","",RANK(B55,$B$2:$B$2471)+COUNTIF($B$2:B55,B55)-1) -> 355
A56: 43885 | B56: 14.5 | C56: 18 | D56: =IF(B56="","",RANK(B56,$B$2:$B$2471)+COUNTIF($B$2:B56,B56)-1) -> 204
... A60: 43889 | B60: 6.2 | C60: 6.6 | D60: =IF(B60="","",RANK(B60,$B$2:$B$2471)+COUNTIF($B$2:B60,B60)-1) -> 432
...

Sheet Horario
A1: Fecha del evento | B1: Hora (inicio) | C1: El Bosque P70 (mm/h) | D1: Clase de intensidad | E1: Suma 3 h (ventana desde esta hora) | F1: Suma 6 h (ventana desde esta hora) | G1: Acumulado del día (mm)
A2: 44592 | B2: 0 | C2: 2.1 | D2: =IF(C2<Parametros!$B$4,"Sin lluvia",IF(C2<Parametros!$B$5,"Ligera",IF(C2<=Parametros!$B$6,"Moderada",IF(C2<=Parametros!$B$7,"Fuerte","Violenta")))) -> Ligera | E2: =IF(A4=A2,SUM(C2:C4),"") -> 3.6 | F2: =IF(A7=A2,SUM(C2:C7),"") -> 11 | G2: =C2 -> 2.1
A3: 44592 | B3: 1 | C3: 0.6 | D3: =IF(C3<Parametros!$B$4,"Sin lluvia",IF(C3<Parametros!$B$5,"Ligera",IF(C3<=Parametros!$B$6,"Moderada",IF(C3<=Parametros!$B$7,"Fuerte","Violenta")))) -> Ligera | E3: =IF(A5=A3,SUM(C3:C5),"") -> 2 | F3: =IF(A8=A3,SUM(C3:C8),"") -> 10.7 | G3: =G2+C3 -> 2.7
A4: 44592 | B4: 2 | C4: 0.9 | D4: =IF(C4<Parametros!$B$4,"Sin lluvia",IF(C4<Parametros!$B$5,"Ligera",IF(C4<=Parametros!$B$6,"Moderada",IF(C4<=Parametros!$B$7,"Fuerte","Violenta")))) -> Ligera | E4: =IF(A6=A4,SUM(C4:C6),"") -> 5.6 | F4: =IF(A9=A4,SUM(C4:C9),"") -> 10.7 | G4: =G3+C4 -> 3.6
A5: 44592 | B5: 3 | C5: 0.5 | D5: =IF(C5<Parametros!$B$4,"Sin lluvia",IF(C5<Parametros!$B$5,"Ligera",IF(C5<=Parametros!$B$6,"Moderada",IF(C5<=Parametros!$B$7,"Fuerte","Violenta")))) -> Ligera | E5: =IF(A7=A5,SUM(C5:C7),"") -> 7.4 | F5: =IF(A10=A5,SUM(C5:C10),"") -> 10.3 | G5: =G4+C5 -> 4.1
A6: 44592 | B6: 4 | C6: 4.2 | D6: =IF(C6<Parametros!$B$4,"Sin lluvia",IF(C6<Parametros!$B$5,"Ligera",IF(C6<=Parametros!$B$6,"Moderada",IF(C6<=Parametros!$B$7,"Fuerte","Violenta")))) -> Moderada | E6: =IF(A8=A6,SUM(C6:C8),"") -> 8.7 | F6: =IF(A11=A6,SUM(C6:C11),"") -> 11.3 | G6: =G5+C6 -> 8.3
A7: 44592 | B7: 5 | C7: 2.7 | D7: =IF(C7<Parametros!$B$4,"Sin lluvia",IF(C7<Parametros!$B$5,"Ligera",IF(C7<=Parametros!$B$6,"Moderada",IF(C7<=Parametros!$B$7,"Fuerte","Violenta")))) -> Moderada | E7: =IF(A9=A7,SUM(C7:C9),"") -> 5.1 | F7: =IF(A12=A7,SUM(C7:C12),"") -> 16.2 | G7: =G6+C7 -> 11
A8: 44592 | B8: 6 | C8: 1.8 | D8: =IF(C8<Parametros!$B$4,"Sin lluvia",IF(C8<Parametros!$B$5,"Ligera",IF(C8<=Parametros!$B$6,"Moderada",IF(C8<=Parametros!$B$7,"Fuerte","Violenta")))) -> Ligera | E8: =IF(A10=A8,SUM(C8:C10),"") -> 2.9 | F8: =IF(A13=A8,SUM(C8:C13),"") -> 18.2 | G8: =G7+C8 -> 12.8
A9: 44592 | B9: 7 | C9: 0.6 | D9: =IF(C9<Parametros!$B$4,"Sin lluvia",IF(C9<Parametros!$B$5,"Ligera",IF(C9<=Parametros!$B$6,"Moderada",IF(C9<=Parametros!$B$7,"Fuerte","Violenta")))) -> Ligera | E9: =IF(A11=A9,SUM(C9:C11),"") -> 2.6 | F9: =IF(A14=A9,SUM(C9:C14),"") -> 16.9 | G9: =G8+C9 -> 13.4
A10: 44592 | B10: 8 | C10: 0.5 | D10: =IF(C10<Parametros!$B$4,"Sin lluvia",IF(C10<Parametros!$B$5,"Ligera",IF(C10<=Parametros!$B$6,"Moderada",IF(C10<=Parametros!$B$7,"Fuerte","Violenta")))) -> Ligera | E10: =IF(A12=A10,SUM(C10:C12),"") -> 11.1 | F10: =IF(A15=A10,SUM(C10:C15),"") -> 18.6 | G10: =G9+C10 -> 13.9
A11: 44592 | B11: 9 | C11: 1.5 | D11: =IF(C11<Parametros!$B$4,"Sin lluvia",IF(C11<Parametros!$B$5,"Ligera",IF(C11<=Parametros!$B$6,"Moderada",IF(C11<=Parametros!$B$7,"Fuerte","Violenta")))) -> Ligera | E11: =IF(A13=A11,SUM(C11:C13),"") -> 15.3 | F11: =IF(A16=A11,SUM(C11:C16),"") -> 20.3 | G11: =G10+C11 -> 15.4
A12: 44592 | B12: 10 | C12: 9.1 | D12: =IF(C12<Parametros!$B$4,"Sin lluvia",IF(C12<Parametros!$B$5,"Ligera",IF(C12<=Parametros!$B$6,"Moderada",IF(C12<=Parametros!$B$7,"Fuerte","Violenta")))) -> Fuerte | E12: =IF(A14=A12,SUM(C12:C14),"") -> 14.3 | F12: =IF(A17=A12,SUM(C12:C17),"") -> 22.5 | G12: =G11+C12 -> 24.5
A13: 44592 | B13: 11 | C13: 4.7 | D13: =IF(C13<Parametros!$B$4,"Sin lluvia",IF(C13<Parametros!$B$5,"Ligera",IF(C13<=Parametros!$B$6,"Moderada",IF(C13<=Parametros!$B$7,"Fuerte","Violenta")))) -> Moderada | E13: =IF(A15=A13,SUM(C13:C15),"") -> 7.5 | F13: =IF(A18=A13,SUM(C13:C18),"") -> 22.2 | G13: =G12+C13 -> 29.2
A14: 44592 | B14: 12 | C14: 0.5 | D14: =IF(C14<Parametros!$B$4,"Sin lluvia",IF(C14<Parametros!$B$5,"Ligera",IF(C14<=Parametros!$B$6,"Moderada",IF(C14<=Parametros!$B$7,"Fuerte","Violenta")))) -> Ligera | E14: =IF(A16=A14,SUM(C14:C16),"") -> 5 | F14: =IF(A19=A14,SUM(C14:C19),"") -> 22.5 | G14: =G13+C14 -> 29.7
... A25: 44592 | B25: 23 | C25: 0 | D25: =IF(C25<Parametros!$B$4,"Sin lluvia",IF(C25<Parametros!$B$5,"Ligera",IF(C25<=Parametros!$B$6,"Moderada",IF(C25<=Parametros!$B$7,"Fuerte","Violenta")))) -> Sin lluvia | E25: =IF(A27=A25,SUM(C25:C27),"") | F25: =IF(A30=A25,SUM(C25:C30),"") | G25: =G24+C25 -> 55.3
A26: 45384 | B26: 0 | C26: 6.3 | D26: =IF(C26<Parametros!$B$4,"Sin lluvia",IF(C26<Parametros!$B$5,"Ligera",IF(C26<=Parametros!$B$6,"Moderada",IF(C26<=Parametros!$B$7,"Fuerte","Violenta")))) -> Moderada | E26: =IF(A28=A26,SUM(C26:C28),"") -> 22 | F26: =IF(A31=A26,SUM(C26:C31),"") -> 22 | G26: =C26 -> 6.3
A27: 45384 | B27: 1 | C27: 14.4 | D27: =IF(C27<Parametros!$B$4,"Sin lluvia",IF(C27<Parametros!$B$5,"Ligera",IF(C27<=Parametros!$B$6,"Moderada",IF(C27<=Parametros!$B$7,"Fuerte","Violenta")))) -> Fuerte | E27: =IF(A29=A27,SUM(C27:C29),"") -> 15.7 | F27: =IF(A32=A27,SUM(C27:C32),"") -> 23.2 | G27: =G26+C27 -> 20.7
A28: 45384 | B28: 2 | C28: 1.3 | D28: =IF(C28<Parametros!$B$4,"Sin lluvia",IF(C28<Parametros!$B$5,"Ligera",IF(C28<=Parametros!$B$6,"Moderada",IF(C28<=Parametros!$B$7,"Fuerte","Violenta")))) -> Ligera | E28: =IF(A30=A28,SUM(C28:C30),"") -> 1.3 | F28: =IF(A33=A28,SUM(C28:C33),"") -> 17.8 | G28: =G27+C28 -> 22
A29: 45384 | B29: 3 | C29: 0 | D29: =IF(C29<Parametros!$B$4,"Sin lluvia",IF(C29<Parametros!$B$5,"Ligera",IF(C29<=Parametros!$B$6,"Moderada",IF(C29<=Parametros!$B$7,"Fuerte","Violenta")))) -> Sin lluvia | E29: =IF(A31=A29,SUM(C29:C31),"") -> 0 | F29: =IF(A34=A29,SUM(C29:C34),"") -> 21.6 | G29: =G28+C29 -> 22
A30: 45384 | B30: 4 | C30: 0 | D30: =IF(C30<Parametros!$B$4,"Sin lluvia",IF(C30<Parametros!$B$5,"Ligera",IF(C30<=Parametros!$B$6,"Moderada",IF(C30<=Parametros!$B$7,"Fuerte","Violenta")))) -> Sin lluvia | E30: =IF(A32=A30,SUM(C30:C32),"") -> 7.5 | F30: =IF(A35=A30,SUM(C30:C35),"") -> 28.2 | G30: =G29+C30 -> 22
A31: 45384 | B31: 5 | C31: 0 | D31: =IF(C31<Parametros!$B$4,"Sin lluvia",IF(C31<Parametros!$B$5,"Ligera",IF(C31<=Parametros!$B$6,"Moderada",IF(C31<=Parametros!$B$7,"Fuerte","Violenta")))) -> Sin lluvia | E31: =IF(A33=A31,SUM(C31:C33),"") -> 16.5 | F31: =IF(A36=A31,SUM(C31:C36),"") -> 28.3 | G31: =G30+C31 -> 22
A32: 45384 | B32: 6 | C32: 7.5 | D32: =IF(C32<Parametros!$B$4,"Sin lluvia",IF(C32<Parametros!$B$5,"Ligera",IF(C32<=Parametros!$B$6,"Moderada",IF(C32<=Parametros!$B$7,"Fuerte","Violenta")))) -> Moderada | E32: =IF(A34=A32,SUM(C32:C34),"") -> 21.6 | F32: =IF(A37=A32,SUM(C32:C37),"") -> 28.3 | G32: =G31+C32 -> 29.5
A33: 45384 | B33: 7 | C33: 9 | D33: =IF(C33<Parametros!$B$4,"Sin lluvia",IF(C33<Parametros!$B$5,"Ligera",IF(C33<=Parametros!$B$6,"Moderada",IF(C33<=Parametros!$B$7,"Fuerte","Violenta")))) -> Fuerte | E33: =IF(A35=A33,SUM(C33:C35),"") -> 20.7 | F33: =IF(A38=A33,SUM(C33:C38),"") -> 20.8 | G33: =G32+C33 -> 38.5
A34: 45384 | B34: 8 | C34: 5.1 | D34: =IF(C34<Parametros!$B$4,"Sin lluvia",IF(C34<Parametros!$B$5,"Ligera",IF(C34<=Parametros!$B$6,"Moderada",IF(C34<=Parametros!$B$7,"Fuerte","Violenta")))) -> Moderada | E34: =IF(A36=A34,SUM(C34:C36),"") -> 11.8 | F34: =IF(A39=A34,SUM(C34:C39),"") -> 16.6 | G34: =G33+C34 -> 43.6
A35: 45384 | B35: 9 | C35: 6.6 | D35: =IF(C35<Parametros!$B$4,"Sin lluvia",IF(C35<Parametros!$B$5,"Ligera",IF(C35<=Parametros!$B$6,"Moderada",IF(C35<=Parametros!$B$7,"Fuerte","Violenta")))) -> Moderada | E35: =IF(A37=A35,SUM(C35:C37),"") -> 6.7 | F35: =IF(A40=A35,SUM(C35:C40),"") -> 18.8 | G35: =G34+C35 -> 50.2
A36: 45384 | B36: 10 | C36: 0.1 | D36: =IF(C36<Parametros!$B$4,"Sin lluvia",IF(C36<Parametros!$B$5,"Ligera",IF(C36<=Parametros!$B$6,"Moderada",IF(C36<=Parametros!$B$7,"Fuerte","Violenta")))) -> Ligera | E36: =IF(A38=A36,SUM(C36:C38),"") -> 0.1 | F36: =IF(A41=A36,SUM(C36:C41),"") -> 13.5 | G36: =G35+C36 -> 50.3
A37: 45384 | B37: 11 | C37: 0 | D37: =IF(C37<Parametros!$B$4,"Sin lluvia",IF(C37<Parametros!$B$5,"Ligera",IF(C37<=Parametros!$B$6,"Moderada",IF(C37<=Parametros!$B$7,"Fuerte","Violenta")))) -> Sin lluvia | E37: =IF(A39=A37,SUM(C37:C39),"") -> 4.8 | F37: =IF(A42=A37,SUM(C37:C42),"") -> 17 | G37: =G36+C37 -> 50.3
A38: 45384 | B38: 12 | C38: 0 | D38: =IF(C38<Parametros!$B$4,"Sin lluvia",IF(C38<Parametros!$B$5,"Ligera",IF(C38<=Parametros!$B$6,"Moderada",IF(C38<=Parametros!$B$7,"Fuerte","Violenta")))) -> Sin lluvia | E38: =IF(A40=A38,SUM(C38:C40),"") -> 12.1 | F38: =IF(A43=A38,SUM(C38:C43),"") -> 20.1 | G38: =G37+C38 -> 50.3
... A49: 45384 | B49: 23 | C49: 0.1 | D49: =IF(C49<Parametros!$B$4,"Sin lluvia",IF(C49<Parametros!$B$5,"Ligera",IF(C49<=Parametros!$B$6,"Moderada",IF(C49<=Parametros!$B$7,"Fuerte","Violenta")))) -> Ligera | E49: =IF(A51=A49,SUM(C49:C51),"") | F49: =IF(A54=A49,SUM(C49:C54),"") | G49: =G48+C49 -> 75.4
A50: 46044 | B50: 0 | C50: 0.2 | D50: =IF(C50<Parametros!$B$4,"Sin lluvia",IF(C50<Parametros!$B$5,"Ligera",IF(C50<=Parametros!$B$6,"Moderada",IF(C50<=Parametros!$B$7,"Fuerte","Violenta")))) -> Ligera | E50: =IF(A52=A50,SUM(C50:C52),"") -> 0.8 | F50: =IF(A55=A50,SUM(C50:C55),"") -> 10.2 | G50: =C50 -> 0.2
A51: 46044 | B51: 1 | C51: 0.4 | D51: =IF(C51<Parametros!$B$4,"Sin lluvia",IF(C51<Parametros!$B$5,"Ligera",IF(C51<=Parametros!$B$6,"Moderada",IF(C51<=Parametros!$B$7,"Fuerte","Violenta")))) -> Ligera | E51: =IF(A53=A51,SUM(C51:C53),"") -> 2.7 | F51: =IF(A56=A51,SUM(C51:C56),"") -> 23 | G51: =G50+C51 -> 0.6
A52: 46044 | B52: 2 | C52: 0.2 | D52: =IF(C52<Parametros!$B$4,"Sin lluvia",IF(C52<Parametros!$B$5,"Ligera",IF(C52<=Parametros!$B$6,"Moderada",IF(C52<=Parametros!$B$7,"Fuerte","Violenta")))) -> Ligera | E52: =IF(A54=A52,SUM(C52:C54),"") -> 7 | F52: =IF(A57=A52,SUM(C52:C57),"") -> 29.9 | G52: =G51+C52 -> 0.8
A53: 46044 | B53: 3 | C53: 2.1 | D53: =IF(C53<Parametros!$B$4,"Sin lluvia",IF(C53<Parametros!$B$5,"Ligera",IF(C53<=Parametros!$B$6,"Moderada",IF(C53<=Parametros!$B$7,"Fuerte","Violenta")))) -> Ligera | E53: =IF(A55=A53,SUM(C53:C55),"") -> 9.4 | F53: =IF(A58=A53,SUM(C53:C58),"") -> 33.1 | G53: =G52+C53 -> 2.9
A54: 46044 | B54: 4 | C54: 4.7 | D54: =IF(C54<Parametros!$B$4,"Sin lluvia",IF(C54<Parametros!$B$5,"Ligera",IF(C54<=Parametros!$B$6,"Moderada",IF(C54<=Parametros!$B$7,"Fuerte","Violenta")))) -> Moderada | E54: =IF(A56=A54,SUM(C54:C56),"") -> 20.3 | F54: =IF(A59=A54,SUM(C54:C59),"") -> 31.3 | G54: =G53+C54 -> 7.6
A55: 46044 | B55: 5 | C55: 2.6 | D55: =IF(C55<Parametros!$B$4,"Sin lluvia",IF(C55<Parametros!$B$5,"Ligera",IF(C55<=Parametros!$B$6,"Moderada",IF(C55<=Parametros!$B$7,"Fuerte","Violenta")))) -> Moderada | E55: =IF(A57=A55,SUM(C55:C57),"") -> 22.9 | F55: =IF(A60=A55,SUM(C55:C60),"") -> 28 | G55: =G54+C55 -> 10.2
A56: 46044 | B56: 6 | C56: 13 | D56: =IF(C56<Parametros!$B$4,"Sin lluvia",IF(C56<Parametros!$B$5,"Ligera",IF(C56<=Parametros!$B$6,"Moderada",IF(C56<=Parametros!$B$7,"Fuerte","Violenta")))) -> Fuerte | E56: =IF(A58=A56,SUM(C56:C58),"") -> 23.7 | F56: =IF(A61=A56,SUM(C56:C61),"") -> 25.4 | G56: =G55+C56 -> 23.2
A57: 46044 | B57: 7 | C57: 7.3 | D57: =IF(C57<Parametros!$B$4,"Sin lluvia",IF(C57<Parametros!$B$5,"Ligera",IF(C57<=Parametros!$B$6,"Moderada",IF(C57<=Parametros!$B$7,"Fuerte","Violenta")))) -> Moderada | E57: =IF(A59=A57,SUM(C57:C59),"") -> 11 | F57: =IF(A62=A57,SUM(C57:C62),"") -> 12.4 | G57: =G56+C57 -> 30.5
A58: 46044 | B58: 8 | C58: 3.4 | D58: =IF(C58<Parametros!$B$4,"Sin lluvia",IF(C58<Parametros!$B$5,"Ligera",IF(C58<=Parametros!$B$6,"Moderada",IF(C58<=Parametros!$B$7,"Fuerte","Violenta")))) -> Moderada | E58: =IF(A60=A58,SUM(C58:C60),"") -> 5.1 | F58: =IF(A63=A58,SUM(C58:C63),"") -> 5.1 | G58: =G57+C58 -> 33.9
A59: 46044 | B59: 9 | C59: 0.3 | D59: =IF(C59<Parametros!$B$4,"Sin lluvia",IF(C59<Parametros!$B$5,"Ligera",IF(C59<=Parametros!$B$6,"Moderada",IF(C59<=Parametros!$B$7,"Fuerte","Violenta")))) -> Ligera | E59: =IF(A61=A59,SUM(C59:C61),"") -> 1.7 | F59: =IF(A64=A59,SUM(C59:C64),"") -> 1.9 | G59: =G58+C59 -> 34.2
A60: 46044 | B60: 10 | C60: 1.4 | D60: =IF(C60<Parametros!$B$4,"Sin lluvia",IF(C60<Parametros!$B$5,"Ligera",IF(C60<=Parametros!$B$6,"Moderada",IF(C60<=Parametros!$B$7,"Fuerte","Violenta")))) -> Ligera | E60: =IF(A62=A60,SUM(C60:C62),"") -> 1.4 | F60: =IF(A65=A60,SUM(C60:C65),"") -> 6.9 | G60: =G59+C60 -> 35.6
...

Sheet Indicadores
A1: Indicadores de intensidad por evento (todo con fórmulas)
A3: Indicador | B3: 44592 | C3: 45384 | D3: 46044 | E3: 46299
A4: Etiqueta | B4: Aluvión de La Gasca | C4: 1.er total diario del registro | D4: 2.º total diario del registro | E4: Evento analizado
A5: Total diario P70 (mm) | B5: =SUMIFS(Diario!$B$2:$B$2471,Diario!$A$2:$A$2471,B$3) -> 55.3 | C5: =SUMIFS(Diario!$B$2:$B$2471,Diario!$A$2:$A$2471,C$3) -> 75.4 | D5: =SUMIFS(Diario!$B$2:$B$2471,Diario!$A$2:$A$2471,D$3) -> 72.9 | E5: =SUMIFS(Diario!$B$2:$B$2471,Diario!$A$2:$A$2471,E$3) -> 64.3
A6: Suma horaria (mm) | B6: =SUMIFS(Horario!$C$2:$C$97,Horario!$A$2:$A$97,B$3) -> 55.3 | C6: =SUMIFS(Horario!$C$2:$C$97,Horario!$A$2:$A$97,C$3) -> 75.4 | D6: =SUMIFS(Horario!$C$2:$C$97,Horario!$A$2:$A$97,D$3) -> 72.9 | E6: =SUMIFS(Horario!$C$2:$C$97,Horario!$A$2:$A$97,E$3) -> 64.2
A7: Diferencia horaria − diaria (mm) | B7: =B6-B5 -> 0 | C7: =C6-C5 -> 0 | D7: =D6-D5 -> 0 | E7: =E6-E5 -> -0.1
A8: Hora más intensa (mm/h) | B8: =_xlfn.MAXIFS(Horario!$C$2:$C$97,Horario!$A$2:$A$97,B$3) -> 9.1 | C8: =_xlfn.MAXIFS(Horario!$C$2:$C$97,Horario!$A$2:$A$97,C$3) -> 14.4 | D8: =_xlfn.MAXIFS(Horario!$C$2:$C$97,Horario!$A$2:$A$97,D$3) -> 13 | E8: =_xlfn.MAXIFS(Horario!$C$2:$C$97,Horario!$A$2:$A$97,E$3) -> 52.2
A9: Hora del pico | B9: =INDEX(Horario!$B$2:$B$97,MATCH(1,INDEX((Horario!$A$2:$A$97=B$3)*(Horario!$C$2:$C$97=B8),0),0)) -> 10 | C9: =INDEX(Horario!$B$2:$B$97,MATCH(1,INDEX((Horario!$A$2:$A$97=C$3)*(Horario!$C$2:$C$97=C8),0),0)) -> 1 | D9: =INDEX(Horario!$B$2:$B$97,MATCH(1,INDEX((Horario!$A$2:$A$97=D$3)*(Horario!$C$2:$C$97=D8),0),0)) -> 6 | E9: =INDEX(Horario!$B$2:$B$97,MATCH(1,INDEX((Horario!$A$2:$A$97=E$3)*(Horario!$C$2:$C$97=E8),0),0)) -> 14
A10: Máximo en 3 horas seguidas (mm) | B10: =_xlfn.MAXIFS(Horario!$E$2:$E$97,Horario!$A$2:$A$97,B$3) -> 17.5 | C10: =_xlfn.MAXIFS(Horario!$E$2:$E$97,Horario!$A$2:$A$97,C$3) -> 22 | D10: =_xlfn.MAXIFS(Horario!$E$2:$E$97,Horario!$A$2:$A$97,D$3) -> 23.7 | E10: =_xlfn.MAXIFS(Horario!$E$2:$E$97,Horario!$A$2:$A$97,E$3) -> 63.8
A11: Máximo en 6 horas seguidas (mm) | B11: =_xlfn.MAXIFS(Horario!$F$2:$F$97,Horario!$A$2:$A$97,B$3) -> 24.6 | C11: =_xlfn.MAXIFS(Horario!$F$2:$F$97,Horario!$A$2:$A$97,C$3) -> 28.3 | D11: =_xlfn.MAXIFS(Horario!$F$2:$F$97,Horario!$A$2:$A$97,D$3) -> 33.1 | E11: =_xlfn.MAXIFS(Horario!$F$2:$F$97,Horario!$A$2:$A$97,E$3) -> 63.9
A12: Peso de la hora pico en el total diario | B12: =B8/B5 -> 0.16455696 | C12: =C8/C5 -> 0.19098143 | D12: =D8/D5 -> 0.17832647 | E12: =E8/E5 -> 0.8118196
A13: Horas con lluvia ≥ umbral | B13: =COUNTIFS(Horario!$A$2:$A$97,B$3,Horario!$C$2:$C$97,">="&Parametros!$B$8) -> 13 | C13: =COUNTIFS(Horario!$A$2:$A$97,C$3,Horario!$C$2:$C$97,">="&Parametros!$B$8) -> 14 | D13: =COUNTIFS(Horario!$A$2:$A$97,D$3,Horario!$C$2:$C$97,">="&Parametros!$B$8) -> 15 | E13: =COUNTIFS(Horario!$A$2:$A$97,E$3,Horario!$C$2:$C$97,">="&Parametros!$B$8) -> 3
A14: Tiempo para acumular el umbral (h) | B14: =_xlfn.MINIFS(Horario!$B$2:$B$97,Horario!$A$2:$A$97,B$3,Horario!$G$2:$G$97,">="&Parametros!$B$9)-_xlfn.MINIFS(Horario!$B$2:$B$97,Horario!$A$2:$A$97,B$3,Horario!$C$2:$C$97,">="&Parametros!$B$8)+1 -> 18 | C14: =_xlfn.MINIFS(Horario!$B$2:$B$97,Horario!$A$2:$A$97,C$3,Horario!$G$2:$G$97,">="&Parametros!$B$9)-_xlfn.MINIFS(Horario!$B$2:$B$97,Horario!$A$2:$A$97,C$3,Horario!$C$2:$C$97,">="&Parametros!$B$8)+1 -> 10 | D14: =_xlfn.MINIFS(Horario!$B$2:$B$97,Horario!$A$2:$A$97,D$3,Horario!$G$2:$G$97,">="&Parametros!$B$9)-_xlfn.MINIFS(Horario!$B$2:$B$97,Horario!$A$2:$A$97,D$3,Horario!$C$2:$C$97,">="&Parametros!$B$8)+1 -> 17 | E14: =_xlfn.MINIFS(Horario!$B$2:$B$97,Horario!$A$2:$A$97,E$3,Horario!$G$2:$G$97,">="&Parametros!$B$9)-_xlfn.MINIFS(Horario!$B$2:$B$97,Horario!$A$2:$A$97,E$3,Horario!$C$2:$C$97,">="&Parametros!$B$8)+1 -> 1
A15: Horas «Fuerte» | B15: =COUNTIFS(Horario!$A$2:$A$97,B$3,Horario!$D$2:$D$97,"Fuerte") -> 2 | C15: =COUNTIFS(Horario!$A$2:$A$97,C$3,Horario!$D$2:$D$97,"Fuerte") -> 2 | D15: =COUNTIFS(Horario!$A$2:$A$97,D$3,Horario!$D$2:$D$97,"Fuerte") -> 2 | E15: =COUNTIFS(Horario!$A$2:$A$97,E$3,Horario!$D$2:$D$97,"Fuerte") -> 1
A16: Horas «Violenta» | B16: =COUNTIFS(Horario!$A$2:$A$97,B$3,Horario!$D$2:$D$97,"Violenta") -> 0 | C16: =COUNTIFS(Horario!$A$2:$A$97,C$3,Horario!$D$2:$D$97,"Violenta") -> 0 | D16: =COUNTIFS(Horario!$A$2:$A$97,D$3,Horario!$D$2:$D$97,"Violenta") -> 0 | E16: =COUNTIFS(Horario!$A$2:$A$97,E$3,Horario!$D$2:$D$97,"Violenta") -> 1
A17: Lluvia previa 3 días (mm, sin el día) | B17: =SUMIFS(Diario!$B$2:$B$2471,Diario!$A$2:$A$2471,">="&(B$3-3),Diario!$A$2:$A$2471,"<"&B$3) -> 64.5 | C17: =SUMIFS(Diario!$B$2:$B$2471,Diario!$A$2:$A$2471,">="&(C$3-3),Diario!$A$2:$A$2471,"<"&C$3) -> 58.3 | D17: =SUMIFS(Diario!$B$2:$B$2471,Diario!$A$2:$A$2471,">="&(D$3-3),Diario!$A$2:$A$2471,"<"&D$3) -> 1.1 | E17: =SUMIFS(Diario!$B$2:$B$2471,Diario!$A$2:$A$2471,">="&(E$3-3),Diario!$A$2:$A$2471,"<"&E$3) -> 15.1
A18: Lluvia previa 30 días (mm, sin el día) | B18: =SUMIFS(Diario!$B$2:$B$2471,Diario!$A$2:$A$2471,">="&(B$3-30),Diario!$A$2:$A$2471,"<"&B$3) -> 147.4 | C18: =SUMIFS(Diario!$B$2:$B$2471,Diario!$A$2:$A$2471,">="&(C$3-30),Diario!$A$2:$A$2471,"<"&C$3) -> 165.6 | D18: =SUMIFS(Diario!$B$2:$B$2471,Diario!$A$2:$A$2471,">="&(D$3-30),Diario!$A$2:$A$2471,"<"&D$3) -> 69.3 | E18: =SUMIFS(Diario!$B$2:$B$2471,Diario!$A$2:$A$2471,">="&(E$3-30),Diario!$A$2:$A$2471,"<"&E$3) -> 47.2
A19: Posición por total diario (P70) | B19: =INDEX(Diario!$D$2:$D$2471,MATCH(B$3,Diario!$A$2:$A$2471,0)) -> 4 | C19: =INDEX(Diario!$D$2:$D$2471,MATCH(C$3,Diario!$A$2:$A$2471,0)) -> 1 | D19: =INDEX(Diario!$D$2:$D$2471,MATCH(D$3,Diario!$A$2:$A$2471,0)) -> 2 | E19: =INDEX(Diario!$D$2:$D$2471,MATCH(E$3,Diario!$A$2:$A$2471,0)) -> 3
A20: Tipo de evento (peso pico ≥ 50 %) | B20: =IF(B12>=0.5,"Concentrado","Larga duración") -> Larga duración | C20: =IF(C12>=0.5,"Concentrado","Larga duración") -> Larga duración | D20: =IF(D12>=0.5,"Concentrado","Larga duración") -> Larga duración | E20: =IF(E12>=0.5,"Concentrado","Larga duración") -> Concentrado
A23: Evento 04/10/2026 frente a los otros tres
A24: Razón | B24: vs 31/01/2022 | C24: vs 02/04/2024 | D24: vs 22/01/2026 | E24: vs máximo de los tres
A25: Hora más intensa (×) | B25: =$E$8/B8 -> 5.7362637 | C25: =$E$8/C8 -> 3.625 | D25: =$E$8/D8 -> 4.0153846 | E25: =$E$8/MAX(B8:D8) -> 3.625
A26: Máximo 3 h (×) | B26: =$E$10/B10 -> 3.6457143 | C26: =$E$10/C10 -> 2.9 | D26: =$E$10/D10 -> 2.6919831 | E26: =$E$10/MAX(B10:D10) -> 2.6919831
A27: Máximo 6 h (×) | B27: =$E$11/B11 -> 2.597561 | C27: =$E$11/C11 -> 2.2579505 | D27: =$E$11/D11 -> 1.9305136 | E27: =$E$11/MAX(B11:D11) -> 1.9305136

Sheet Top_diario
A1: Mayores totales diarios en El Bosque (P70), 2020–2026
A3: Posición | B3: Fecha | C3: mm en el día | D3: Días con dato (P70)
A4: 1 | B4: =INDEX(Diario!$A$2:$A$2471,MATCH(A4,Diario!$D$2:$D$2471,0)) -> 45384 | C4: =INDEX(Diario!$B$2:$B$2471,MATCH(A4,Diario!$D$2:$D$2471,0)) -> 75.4 | D4: =COUNT(Diario!$B$2:$B$2471) -> 2296
A5: 2 | B5: =INDEX(Diario!$A$2:$A$2471,MATCH(A5,Diario!$D$2:$D$2471,0)) -> 46044 | C5: =INDEX(Diario!$B$2:$B$2471,MATCH(A5,Diario!$D$2:$D$2471,0)) -> 72.9
A6: 3 | B6: =INDEX(Diario!$A$2:$A$2471,MATCH(A6,Diario!$D$2:$D$2471,0)) -> 46299 | C6: =INDEX(Diario!$B$2:$B$2471,MATCH(A6,Diario!$D$2:$D$2471,0)) -> 64.3
A7: 4 | B7: =INDEX(Diario!$A$2:$A$2471,MATCH(A7,Diario!$D$2:$D$2471,0)) -> 44592 | C7: =INDEX(Diario!$B$2:$B$2471,MATCH(A7,Diario!$D$2:$D$2471,0)) -> 55.3
A8: 5 | B8: =INDEX(Diario!$A$2:$A$2471,MATCH(A8,Diario!$D$2:$D$2471,0)) -> 44542 | C8: =INDEX(Diario!$B$2:$B$2471,MATCH(A8,Diario!$D$2:$D$2471,0)) -> 55
A9: 6 | B9: =INDEX(Diario!$A$2:$A$2471,MATCH(A9,Diario!$D$2:$D$2471,0)) -> 45639 | C9: =INDEX(Diario!$B$2:$B$2471,MATCH(A9,Diario!$D$2:$D$2471,0)) -> 50.3
A10: 7 | B10: =INDEX(Diario!$A$2:$A$2471,MATCH(A10,Diario!$D$2:$D$2471,0)) -> 44974 | C10: =INDEX(Diario!$B$2:$B$2471,MATCH(A10,Diario!$D$2:$D$2471,0)) -> 49.5
A11: 8 | B11: =INDEX(Diario!$A$2:$A$2471,MATCH(A11,Diario!$D$2:$D$2471,0)) -> 45037 | C11: =INDEX(Diario!$B$2:$B$2471,MATCH(A11,Diario!$D$2:$D$2471,0)) -> 49.5
A12: 9 | B12: =INDEX(Diario!$A$2:$A$2471,MATCH(A12,Diario!$D$2:$D$2471,0)) -> 45038 | C12: =INDEX(Diario!$B$2:$B$2471,MATCH(A12,Diario!$D$2:$D$2471,0)) -> 47.9
A13: 10 | B13: =INDEX(Diario!$A$2:$A$2471,MATCH(A13,Diario!$D$2:$D$2471,0)) -> 45956 | C13: =INDEX(Diario!$B$2:$B$2471,MATCH(A13,Diario!$D$2:$D$2471,0)) -> 47.9

Sheet Antecedentes
A1: Precipitación mensual P70 vs P28 (mm), solo meses con registro completo en ambas
A2: Referencia de contexto: el gradiente habitual entre Cruz Loma (ladera) y El Bosque (valle).
A4: Año | B4: Mes | C4: P70 El Bosque | D4: P28 Cruz Loma | E4: Razón P28/P70
A5: 2020 | B5: 3 | C5: 172.1 | D5: 206.1 | E5: =IF(C5>0,D5/C5,"") -> 1.1975596
A6: 2020 | B6: 4 | C6: 169.9 | D6: 316.7 | E6: =IF(C6>0,D6/C6,"") -> 1.8640377
A7: 2020 | B7: 5 | C7: 64.7 | D7: 88.8 | E7: =IF(C7>0,D7/C7,"") -> 1.3724884
A8: 2020 | B8: 6 | C8: 37.5 | D8: 137.4 | E8: =IF(C8>0,D8/C8,"") -> 3.664
A9: 2020 | B9: 7 | C9: 41.6 | D9: 88.8 | E9: =IF(C9>0,D9/C9,"") -> 2.1346154
A10: 2020 | B10: 8 | C10: 37.2 | D10: 69.2 | E10: =IF(C10>0,D10/C10,"") -> 1.8602151
A11: 2020 | B11: 9 | C11: 59.6 | D11: 84.7 | E11: =IF(C11>0,D11/C11,"") -> 1.4211409
A12: 2020 | B12: 10 | C12: 61.3 | D12: 97.1 | E12: =IF(C12>0,D12/C12,"") -> 1.5840131
A13: 2020 | B13: 11 | C13: 139.9 | D13: 171.6 | E13: =IF(C13>0,D13/C13,"") -> 1.2265904
A14: 2020 | B14: 12 | C14: 120.2 | D14: 245.5 | E14: =IF(C14>0,D14/C14,"") -> 2.0424293
A15: 2021 | B15: 2 | C15: 127.1 | D15: 157.5 | E15: =IF(C15>0,D15/C15,"") -> 1.2391817
A16: 2021 | B16: 3 | C16: 294.3 | D16: 366.4 | E16: =IF(C16>0,D16/C16,"") -> 1.2449881
... A57: 2026 | B57: 1 | C57: 216.6 | D57: 380.2 | E57: =IF(C57>0,D57/C57,"") -> 1.7553093
A59: Razón del total | E59: =SUM(D5:D57)/SUM(C5:C57) -> 1.3971133
A60: Los totales mensuales se calcularon desde las series diarias de la hoja Diario (valores, no fórmulas).
